Workbook

Sheet September
A1: Kids | Q1: Salario Mensual | R1: Salario Quincenal
A3: Nombre | B3: Mensual | C3: Quincenal | D3: Es Anual | E3: Costo Anual | F3: Costo Mensual | G3: Comentarios | H3: Cuenta Cargo | I3: Cuenta deposito
A4: Colegiatura Lena | B4: =CEILING(F4,100) -> 17500 | C4: =CEILING(B4/2, 10) -> 8750 | D4: =IF(E4>0, true) -> FALSE | F4: 17500 | H4: HSBC World elite | I4: Uala
A5: Colegiatura Leander | B5: =CEILING(F5,100) -> 12500 | C5: =CEILING(B5/2, 10) -> 6250 | D5: =IF(E5>0, true) -> FALSE | F5: 12500 | H5: Uala | I5: Uala
A6: Clases de aleman | B6: =CEILING(F6,100) -> 4400 | C6: =CEILING(B6/2, 10) -> 2200 | D6: =IF(E6>0, true) -> FALSE | F6: =550*8 -> 4400 | G6: 8 clases al mes (2 clases semanales) | H6: HSBC World elite | I6: HSBC
A7: Gimnasia | B7: =CEILING(F7,100) -> 2500 | C7: =CEILING(B7/2, 10) -> 1250 | D7: =IF(E7>0, true) -> FALSE | F7: 2500 | H7: Uala | I7: Uala
A8: Inscripcion Lena | B8: =CEILING(F8,100) -> 1600 | C8: =CEILING(B8/2, 10) -> 800 | D8: =IF(E8>0, true) -> TRUE | E8: 19000 | F8: =E8/12 -> 1583.3333 | G8: Al menos 50% de la siguiente inscripcion | H8: HSBC World elite | I8: Stori Inversion +
A9: Natacion Lena | B9: =CEILING(F9,100) -> 1300 | C9: =CEILING(B9/2, 10) -> 650 | D9: =IF(E9>0, true) -> FALSE | F9: 1270 | H9: HSBC World elite | I9: Uala
A10: Natacion Leander | B10: =CEILING(F10,100) -> 1300 | C10: =CEILING(B10/2, 10) -> 650 | D10: =IF(E10>0, true) -> FALSE | F10: 1270 | H10: HSBC World elite | I10: Uala
A11: Little Kickers | B11: =CEILING(F11,100) -> 1300 | C11: =CEILING(B11/2, 10) -> 650 | D11: =IF(E11>0, true) -> FALSE | F11: 1250 | H11: HSBC World elite | I11: Uala
A12: Inscripcion Leander | B12: =CEILING(F12,100) -> 1000 | C12: =CEILING(B12/2, 10) -> 500 | D12: =IF(E12>0, true) -> TRUE | E12: 12000 | F12: =E12/12 -> 1000 | H12: Uala | I12: Stori Inversion + | M12: =E8+E14+E22+E23+E25+E27+E28+E53+E54+E56+E72 -> 49839
A15: Total | B15: =SUM(B3:B14) -> 43400 | C15: =SUM(C3:C14) -> 21700 | F15: =SUM(F3:F14) -> 43273.333
A17: Suscripciones | M17: =62517+1700 -> 64217
A19: Nombre | B19: Mensual | C19: Quincenal | D19: Es Anual | H19: Cuenta Cargo | I19: Cuenta Deposito
A20: Sports World | B20: =CEILING(F20,100) -> 3900 | C20: =CEILING(B20/2, 10) -> 1950 | D20: =IF(E20>0, true) -> FALSE | F20: 3850 | H20: HSBC World elite | I20: Nu Cajita Gastos
A21: Netflix | B21: =CEILING(F21,100) -> 400 | C21: =CEILING(B21/2, 10) -> 200 | D21: =IF(E21>0, true) -> FALSE | F21: 350 | H21: 2Now Gastos | I21: Nu Cajita Gastos
A22: NFL game pass | B22: =CEILING(F22,100) -> 300 | C22: =CEILING(B22/2, 10) -> 150 | D22: =IF(E22>0, true) -> TRUE | E22: 3300 | F22: =E22/12 -> 275 | H22: HSBC World elite | I22: Stori Inversion +
A23: Disney | B23: =CEILING(F23,100) -> 200 | C23: =CEILING(B23/2, 10) -> 100 | D23: =IF(E23>0, true) -> TRUE | E23: 2400 | F23: =E23/12 -> 200 | H23: 2Now Gastos | I23: Nu Cajita Gastos
A24: Max | B24: =CEILING(F24,100) -> 200 | C24: =CEILING(B24/2, 10) -> 100 | D24: =IF(E24>0, true) -> FALSE | F24: 199 | H24: 2Now Gastos | I24: Nu Cajita Gastos
A25: Spotify | B25: =CEILING(F25,100) -> 200 | C25: =CEILING(B25/2, 10) -> 100 | D25: =IF(E25>0, true) -> TRUE | E25: 1990 | F25: =E25/12 -> 165.83333 | H25: HSBC World elite | I25: Stori Inversion +
A26: Digital Ocean | B26: =CEILING(F26,100) -> 200 | C26: =CEILING(B26/2, 10) -> 100 | D26: =IF(E26>0, true) -> FALSE | F26: 130 | H26: HSBC World elite | I26: Nu Cajita Gastos
A27: Prime | B27: =CEILING(F27,100) -> 100 | C27: =CEILING(B27/2, 10) -> 50 | D27: =IF(E27>0, true) -> TRUE | E27: 899 | F27: =E27/12 -> 74.916667 | H27: HSBC World elite | I27: Stori Inversion +
A28: Uber one | B28: =CEILING(F28,100) -> 100 | C28: =CEILING(B28/2, 10) -> 50 | D28: =IF(E28>0, true) -> TRUE | E28: 750 | F28: =E28/12 -> 62.5 | H28: HSBC World elite | I28: Stori Inversion +
A29: Frontend masters | B29: =CEILING(F29,100) -> 0 | C29: =CEILING(B29/2, 10) -> 0 | D29: =IF(E29>0, true) -> FALSE | H29: HSBC World elite | I29: Nu Cajita Gastos
A31: Total | B31: =SUM(B20:B29) -> 5600 | C31: =SUM(C20:C29) -> 2800 | F31: =SUM(F20:F29) -> 5307.25
A33: Telecomunicaciones
A34: Nombre | B34: Mensual | C34: Quincenal | D34: Es Anual | H34: Cuenta Cargo | I34: Cuenta Deposito
A35: Totalplay (Internet + TV) | B35: =CEILING(F35,100) -> 1200 | C35: =CEILING(B35/2, 10) -> 600 | D35: =IF(E35>0, true) -> FALSE | F35: 1200 | H35: 2Now Hogar | I35: Nu Cajita Hogar
A36: Movistar Dalia | B36: =CEILING(F36,100) -> 500 | C36: =CEILING(B36/2, 10) -> 250 | D36: =IF(E36>0, true) -> FALSE | F36: 500 | H36: 2Now Gastos | I36: Nu Cajita Gastos
A37: Movistar Alfredo | B37: =CEILING(F37,100) -> 500 | C37: =CEILING(B37/2, 10) -> 250 | D37: =IF(E37>0, true) -> FALSE | F37: 500 | H37: 2Now Gastos | I37: Nu Cajita Gastos
A39: Total | B39: =SUM(B35:B38) -> 2200 | C39: =SUM(C35:C38) -> 1100 | F39: =SUM(F35:F38) -> 2200
A41: Ahorro
A42: Nombre | B42: Mensual | C42: Quincenal | D42: Es Anual | H42: Cuenta Cargo | I42: Cuenta Deposito
A43: Trading | B43: =CEILING(F43,100) -> 800 | C43: =CEILING(B43/2, 10) -> 400 | D43: =IF(E43>0, true) -> FALSE | F43: 800 | H43: HSBC | I43: GBM Trading
A44: Dolares | B44: =CEILING(F44,100) -> 0 | C44: =CEILING(B44/2, 10) -> 0 | D44: =IF(E44>0, true) -> FALSE | H44: HSBC | I44: GBM Dolares
A45: Largo plazo | B45: =CEILING(F45,100) -> 0 | C45: =CEILING(B45/2, 10) -> 0 | D45: =IF(E45>0, true) -> FALSE | H45: Stori Inversion + | I45: Stori Inversion +
A47: Total | B47: =SUM(B43:B45) -> 800 | C47: =SUM(C43:C45) -> 400 | F47: =SUM(F43:F45) -> 800
A49: Auto
A50: Nombre | B50: Mensual | C50: Quincenal | D50: Es Anual | H50: Cuenta Cargo | I50: Cuenta Deposito
A51: Nuevo Auto | B51: =CEILING(F51,100) -> 11000 | C51: =CEILING(B51/2, 10) -> 5500 | D51: =IF(E51>0, true) -> FALSE | F51: 11000 | H51: HSBC | I51: Nu Cajita Auto
...

Sheet September of Totales y Transfer
A1: Column 1 | B1: CLABE | C1: Referencia en deposito | D1: Total Mensual | E1: Total quincenal | F1: Programada
A2: HSBC Flexible | B2: {=INDEX(Table3[CLABE], MATCH(A2, Table3[Nombre cuenta], 0))} -> 021180065930525793 | C2: {=INDEX(Table3[Codigo Referencia], MATCH(A2, Table3[Nombre cuenta], 0))} -> 0000011 | D2: =SUMIF(September!$I$3:$I$88, A2, September!$B$3:$B$88) -> 39300 | E2: =SUMIF(September!$I$3:$I$88, A2, September!$C$3:$C$88) -> 19650 | F2: TRUE | H2: x
A3: Uala | B3: {=INDEX(Table3[CLABE], MATCH(A3, Table3[Nombre cuenta], 0))} -> 138580000023894928 | C3: {=INDEX(Table3[Codigo Referencia], MATCH(A3, Table3[Nombre cuenta], 0))} -> 0000014 | D3: =SUMIF(September!$I$3:$I$88, A3, September!$B$3:$B$88) -> 36400 | E3: =SUMIF(September!$I$3:$I$88, A3, September!$C$3:$C$88) -> 18200 | F3: TRUE | H3: x
A4: Nu Cajita Hogar | B4: {=INDEX(Table3[CLABE], MATCH(A4, Table3[Nombre cuenta], 0))} -> 638180000177404193 | C4: {=INDEX(Table3[Codigo Referencia], MATCH(A4, Table3[Nombre cuenta], 0))} -> 0000016 | D4: =SUMIF(September!$I$3:$I$88, A4, September!$B$3:$B$88) -> 21400 | E4: =SUMIF(September!$I$3:$I$88, A4, September!$C$3:$C$88) -> 10700 | F4: TRUE | H4: x
A5: Nu Cajita Auto | B5: {=INDEX(Table3[CLABE], MATCH(A5, Table3[Nombre cuenta], 0))} -> 638180000177404193 | C5: {=INDEX(Table3[Codigo Referencia], MATCH(A5, Table3[Nombre cuenta], 0))} -> 0000012 | D5: =SUMIF(September!$I$3:$I$88, A5, September!$B$3:$B$88) -> 17200 | E5: =SUMIF(September!$I$3:$I$88, A5, September!$C$3:$C$88) -> 8600 | F5: TRUE | H5: x
A6: HSBC | B6: {=INDEX(Table3[CLABE], MATCH(A6, Table3[Nombre cuenta], 0))} -> 021180040690613986 | C6: {=INDEX(Table3[Codigo Referencia], MATCH(A6, Table3[Nombre cuenta], 0))} -> 0000001 | D6: =SUMIF(September!$I$3:$I$88, A6, September!$B$3:$B$88) -> 13500 | E6: =SUMIF(September!$I$3:$I$88, A6, September!$C$3:$C$88) -> 6750 | F6: FALSE
A7: Nu Cajita Gastos | B7: {=INDEX(Table3[CLABE], MATCH(A7, Table3[Nombre cuenta], 0))} -> 638180000177404193 | C7: {=INDEX(Table3[Codigo Referencia], MATCH(A7, Table3[Nombre cuenta], 0))} -> 0000013 | D7: =SUMIF(September!$I$3:$I$88, A7, September!$B$3:$B$88) -> 11700 | E7: =SUMIF(September!$I$3:$I$88, A7, September!$C$3:$C$88) -> 5850 | F7: TRUE | H7: x
A8: Stori Inversion + | B8: {=INDEX(Table3[CLABE], MATCH(A8, Table3[Nombre cuenta], 0))} -> 646180402300057567 | C8: {=INDEX(Table3[Codigo Referencia], MATCH(A8, Table3[Nombre cuenta], 0))} -> 0000015 | D8: =SUMIF(September!$I$3:$I$88, A8, September!$B$3:$B$88) -> 3400 | E8: =SUMIF(September!$I$3:$I$88, A8, September!$C$3:$C$88) -> 1700 | F8: TRUE | H8: x
A9: Nu Dalia Debito | B9: {=INDEX(Table3[CLABE], MATCH(A9, Table3[Nombre cuenta], 0))} -> 638180010151893079 | C9: {=INDEX(Table3[Codigo Referencia], MATCH(A9, Table3[Nombre cuenta], 0))} -> 0000004 | D9: =SUMIF(September!$I$3:$I$88, A9, September!$B$3:$B$88) -> 2300 | E9: =SUMIF(September!$I$3:$I$88, A9, September!$C$3:$C$88) -> 1150 | F9: TRUE | H9: x
A10: GBM Trading | B10: {=INDEX(Table3[CLABE], MATCH(A10, Table3[Nombre cuenta], 0))} -> 601180400038253515 | C10: {=INDEX(Table3[Codigo Referencia], MATCH(A10, Table3[Nombre cuenta], 0))} -> 0000104 | D10: =SUMIF(September!$I$3:$I$88, A10, September!$B$3:$B$88) -> 800 | E10: =SUMIF(September!$I$3:$I$88, A10, September!$C$3:$C$88) -> 400 | F10: TRUE
A11: GBM Dolares | B11: {=INDEX(Table3[CLABE], MATCH(A11, Table3[Nombre cuenta], 0))} -> 601180400049499232 | C11: {=INDEX(Table3[Codigo Referencia], MATCH(A11, Table3[Nombre cuenta], 0))} -> 0000103 | D11: =SUMIF(September!$I$3:$I$88, A11, September!$B$3:$B$88) -> 0 | E11: =SUMIF(September!$I$3:$I$88, A11, September!$C$3:$C$88) -> 0 | F11: TRUE
C14: Total | D14: =SUM(Current_transactions_2[Total Mensual]) -> 146000 | E14: =SUM(Current_transactions_2[Total quincenal]) -> 73000

Sheet Deuda
A1: Mensualidades
A3: Concepto | B3: Cantidad | C3: # Mensualidades | D3: Mensualidades Pagadas | E3: Mensualidad | F3: Restante | G3: Tarjeta
A4: Gastos Medicos Menores | B4: ='Gastos Medicos Menores'!D60 -> 6354.68 | C4: 1 | D4: 0 | E4: =B4/C4 -> 6354.68 | F4: =B4-(D4*E4) -> 6354.68 | G4: 2Now Gastos
A5: Gastos Generales | B5: ='Gastos Generales'!C84 -> 1736.2 | C5: 1 | D5: 0 | E5: =B5/C5 -> 1736.2 | F5: =B5-(D5*E5) -> 1736.2 | G5: 2Now Gastos
A6: Gastos Medicos Mayores 2Now | B6: ='Gastos Medicos Mayores'!D38 -> 3802 | C6: 1 | D6: 0 | E6: =B6/C6 -> 3802 | F6: =B6-(D6*E6) -> 3802 | G6: 2Now Gastos
A7: Gastos Hogar y Alimentos | B7: ='Gastos Alimentos'!B97 -> 1067.32 | C7: 1 | D7: 0 | E7: =B7/C7 -> 1067.32 | F7: =B7-(D7*E7) -> 1067.32 | G7: 2Now Hogar
A8: Texas 2 | B8: ='Gastos Viaje Texas Dec 25'!B45 -> 18942.52 | C8: 3 | D8: 2 | E8: =B8/C8 -> 6314.1733 | F8: =(C8-D8)*E8 -> 6314.1733 | G8: AMEX
A9: Olinca Enero | B9: 17280 | C9: 3 | D9: 2 | E9: =B9/C9 -> 5760 | F9: =(C9-D9)*E9 -> 5760 | G9: AMEX
A10: Olinca Diciembre | B10: 17280 | C10: 3 | D10: 3 | E10: =B10/C10 -> 5760 | F10: =(C10-D10)*E10 -> 0 | G10: AMEX
A11: Olinca Noviembre | B11: 17280 | C11: 3 | D11: 3 | E11: =B11/C11 -> 5760 | F11: =(C11-D11)*E11 -> 0 | G11: AMEX
A12: AIRBNB | B12: 15024.74 | C12: 3 | D12: 3 | E12: =B12/C12 -> 5008.2467 | F12: =B12-(D12*E12) -> 0 | G12: AMEX
A13: AMEX MSI | B13: 6800 | C13: 9 | D13: 5 | E13: =B13/C13 -> 755.55556 | F13: =(C13-D13)*E13 -> 3022.2222 | G13: AMEX
A14: AMEX Extranjero Dic | B14: =277.93+1303.35+112.81+262.09+1656.25 -> 3612.43 | C14: 3 | D14: 2 | E14: =B14/C14 -> 1204.1433 | F14: =B14-(D14*E14) -> 1204.1433 | G14: AMEX
A15: AMEX | B15: ='Gastos Generales'!C83 -> 0 | C15: 1 | D15: 1 | E15: =(B15/C15)*(C15-D15) -> 0 | F15: =(C15-D15)*E15 -> 0 | G15: AMEX
A16: Gastos Medicos Mayores Amex | B16: ='Gastos Medicos Mayores'!D37 -> 1400 | C16: 1 | D16: 1 | E16: =B16/C16 -> 1400 | F16: =B16-(D16*E16) -> 0 | G16: AMEX
A17: Vuelo Tijuana | B17: 14500 | C17: 3 | D17: 3 | E17: =B17/C17 -> 4833.3333 | F17: =(C17-D17)*E17 -> 0 | G17: AMEX
A18: AMEX Gastos medicos | B18: ='Gastos Medicos Menores'!D59 -> 0 | C18: 1 | D18: 0 | E18: =B18/C18 -> 0 | F18: =B18-(D18*E18) -> 0 | G18: AMEX
A19: Costco | B19: ='Gastos Alimentos'!G97+'Gastos Generales'!C89 -> 0 | C19: 1 | D19: 0 | E19: =(B19/C19)*(C19-D19) -> 0 | F19: =(C19-D19)*E19 -> 0 | G19: Costco
A20: Sala | B20: 37794.6 | C20: 18 | D20: 9 | E20: =B20/C20 -> 2099.7 | F20: =(C20-D20)*E20 -> 18897.3 | G20: HSBC World elite
A21: Texas 1 | B21: ='Gastos Viaje Texas Dec 25'!B12 -> 20555.63 | C21: 6 | D21: 2 | E21: =B21/C21 -> 3425.9383 | F21: =(C21-D21)*E21 -> 13703.753 | G21: HSBC World elite
A22: Happy Holidays | B22: 10246.2 | C22: 6 | D22: 2 | E22: =B22/C22 -> 1707.7 | F22: =(C22-D22)*E22 -> 6830.8 | G22: HSBC World elite
A23: Amazon MSI | B23: 7390.75 | C23: 9 | D23: 3 | E23: =B23/C23 -> 821.19444 | F23: =B23-(D23*E23) -> 4927.1667 | G23: HSBC World elite
A24: Gastos Programados WE | B24: ='Gastos WE'!C65 -> 0 | C24: 1 | D24: 0 | E24: =(B24/C24)*(C24-D24) -> 0 | F24: =(C24-D24)*E24 -> 0 | G24: HSBC World elite
A25: Computadora | B25: 3999 | C25: 6 | D25: 2 | E25: =B25/C25 -> 666.5 | F25: =(C25-D25)*E25 -> 2666 | G25: HSBC World elite
A26: Gastos WE | B26: ='Gastos WE'!G65+'Gastos Medicos Menores'!D61 -> 0 | C26: 1 | D26: 0 | E26: =(B26/C26)*(C26-D26) -> 0 | F26: =(C26-D26)*E26 -> 0 | G26: HSBC World elite
A27: Toys R Us | B27: 2668 | C27: 3 | D27: 2 | E27: =B27/C27 -> 889.33333 | F27: =(C27-D27)*E27 -> 889.33333 | G27: HSBC World elite
A28: iPad | B28: 7653 | C28: 9 | D28: 9 | E28: =B28/C28 -> 850.33333 | F28: =(C28-D28)*E28 -> 0 | G28: HSBC World elite
A29: Master | B29: 4998.84 | C29: 12 | D29: 11 | E29: =B29/C29 -> 416.57 | F29: =(C29-D29)*E29 -> 416.57 | G29: HSBC World elite
A30: Lavadora | B30: 6291 | C30: 9 | D30: 9 | E30: =B30/C30 -> 699 | F30: =(C30-D30)*E30 -> 0 | G30: HSBC World elite
A31: Estufa | B31: 4169 | C31: 9 | D31: 9 | E31: =B31/C31 -> 463.22222 | F31: =(C31-D31)*E31 -> 0 | G31: HSBC World elite
A32: Gastos Medicos WE | B32: ='Gastos Medicos Menores'!D61 -> 0 | C32: 1 | D32: 0 | E32: =B32/C32 -> 0 | F32: =(C32-D32)*E32 -> 0 | G32: HSBC World elite
A33: Bellroy Sling | B33: 3168.41 | C33: 6 | D33: 6 | E33: =B33/C33 -> 528.06833 | F33: =(C33-D33)*E33 -> 0 | G33: HSBC World elite
A34: Dentista | B34: 12244 | C34: 6 | D34: 6 | E34: =B34/C34 -> 2040.6667 | F34: =(C34-D34)*E34 -> 0 | G34: HSBC World elite
A35: La Comer | B35: 13498 | C35: 12 | D35: 12 | E35: =B35/C35 -> 1124.8333 | F35: =(C35-D35)*E35 -> 0 | G35: HSBC World elite
A36: Computadora | B36: 31641.36 | C36: 6 | D36: 1 | E36: =B36/C36 -> 5273.56 | F36: =(C36-D36)*E36 -> 26367.8 | G36: HSBC World elite
A37: Tarjeta Liverpool | B37: ='Gastos Generales'!C85 -> 0 | C37: 1 | D37: 0 | E37: =(B37/C37)*(C37-D37) -> 0 | F37: =(C37-D37)*E37 -> 0 | G37: Liverpool
A38: Tarjeta Nu | B38: ='Gastos Generales'!B88 -> 0 | C38: 1 | D38: 0 | E38: =B38/C38 -> 0 | F38: =B38-(D38*E38) -> 0 | G38: Nu Tarjeta
A39: Tarjeta palacio | B39: ='Gastos Generales'!C86 -> 0 | C39: 1 | D39: 0 | E39: =(B39/C39)*(C39-D39) -> 0 | F39: =(C39-D39)*E39 -> 0 | G39: Palacio de Hierro
A40: Tarjeta Uala | B40: ='Gastos Generales'!C87 -> 8315 | C40: 1 | D40: 0 | E40: =B40/C40 -> 8315 | F40: =B40-(D40*E40) -> 8315 | G40: Uala Credito
A41: Vuelos Houston | B41: 36620 | C41: 6 | D41: 4 | E41: =B41/C41 -> 6103.3333 | F41: =B41-(D41*E41) -> 12206.667 | G41: Volaris
...

Sheet Cuentas
A1: Nombre cuenta | B1: Tipo | C1: Codigo Referencia | D1: Cuenta / Tarjeta | E1: CLABE | J1: Tipos de cuentas
A2: HSBC | B2: Visible | C2: 0000001 | D2: 4069061398 | E2: 021180040690613986 | J2: Ahorro
A3: Santander | B3: Visible | C3: 0000002 | D3: 60567059650 | E3: 014180605670596501 | J3: Visible
A4: BBVA | B4: Visible | C4: 0000003 | D4: 1537717736 | E4: 012180015377177365 | J4: Inversion
A5: Nu Dalia Debito | B5: Visible | C5: 0000004 | E5: 638180010151893079 | J5: Credito
A6: Nu | B6: Visible | C6: 0000005 | D6: 17740419 | E6: 638180000177404193 | J6: Departamental
A7: Stori + | B7: Visible | C7: 0000006 | E7: 646180402300057567
A8: Cetes | B8: Inversion | C8: 0000102 | E8: 135180330008516792
A9: GBM Trading | B9: Inversion | C9: 0000104 | E9: 601180400038253515 | J9: Tipos de gasto
A10: GBM Dolares | B10: Inversion | C10: 0000103 | E10: 601180400049499232 | J10: Estudios y medicamentos
A11: Palacio de Hierro | B11: Departamental | C11: 0000027 | D11: 6620010271451763 | J11: Supermercado
A12: Liverpool | B12: Departamental | C12: 0000029 | E12: 646222162529157954 | J12: Comida para llevar
A13: 2Now Hogar | B13: Credito | C13: 0000022 | D13: 5470748025759733 | E13: 021975211101429027 | J13: Ropa
A14: Rappi | B14: Credito | C14: 0000023 | D14: 4075610085387965 | E14: 646180120624078216 | J14: Servicios
A15: Costco | B15: Credito | C15: 0000024 | E15: 002975010130301365 | J15: Educacion
A16: Volaris | B16: Credito | C16: 0000025 | D16: 5253460005319362 | E16: 059975010021156436 | J16: Actividades
A17: Uala Credito | B17: Credito | C17: 0000025 | J17: Auto
A18: Stori Tarjeta | B18: Credito | C18: 0000026 | D18: 5303460002097136 | E18: 646180224430895806 | J18: Consultas medicas
A19: Nu Tarjeta | B19: Credito | C19: 0000027 | D19: 5267776905329837 | E19: 638975000249369122
A20: HSBC World elite | B20: Credito | C20: 0000028 | D20: 5221748002171250 | E20: 021975211901200792
A21: AMEX | B21: Credito | C21: 0000031 | D21: 371779655281004
A22: 2Now Gastos | B22: Credito | C22: 0000030 | D22: 5470748025758396 | E22: 021975211101429027
A23: HSBC Flexible | B23: Ahorro | C23: 0000011 | E23: 021180065930525793
A24: Nu Cajita Auto | B24: Ahorro | C24: 0000012 | D24: 17740419 | E24: 638180000177404193
A25: Nu Cajita Gastos | B25: Ahorro | C25: 0000013 | D25: 17740419 | E25: 638180000177404193
A26: Nu Cajita Hogar | B26: Ahorro | C26: 0000016 | D26: 17740419 | E26: 638180000177404193
A27: Uala | B27: Ahorro | C27: 0000014 | E27: 138580000023894928
A28: Stori Inversion + | B28: Ahorro | C28: 0000015 | E28: 646180402300057567

Sheet Vacaciones
A1: Cancun Ago 25
A2: Concepto | B2: Monto | C2: Pagado
A3: Hotel Cancun | B3: 27121.12 | C3: Si
A4: Vuelos Cancun | B4: 13536 | C4: Si
A5: Hotel Aeropuerto | B5: 2241.25 | C5: Si
A6: Asientos Vuelo | B6: 1816 | C6: Si
A7: Asientos Vuelo | B7: 1704 | C7: Si
A8: Cena Aeropuerto | B8: 1500 | C8: Si
A9: H&M | B9: 604 | C9: Si
A10: Starbucks Cancun Aeropuerto | B10: 558 | C10: Si
A11: Gasolina Auto Renta | B11: 320.97 | C11: Si
A12: Uber Aeropuerto | B12: 282.58 | C12: Si
A13: Tienda Aeropuerto CUN | B13: 228 | C13: Si
A14: Wifi | B14: 150.85 | C14: Si
A15: Wifi | B15: 148.41 | C15: Si
A16: Renta auto | B16: =3420.5+382.88 -> 3803.38 | C16: Si
B26: =SUM(B3:B20) -> 54014.56

Sheet Gastos Alimentos
A1: 2Now Super | C1: Pagado | D1: Fecha | F1: Costco | H1: Pagado
A2: Concepto | C2: TRUE | F2: Compra mensual | G2: =9959+255 -> 10214 | H2: TRUE
A3: Toks | B3: 672.7 | C3: FALSE | F3: Membresia | G3: 1200 | H3: TRUE
A4: Uber eats | B4: 241.96 | C4: FALSE | F4: Costco | G4: 3891.5 | H4: TRUE
A5: Uber eats | B5: 25.66 | C5: FALSE | F5: Compras casa | G5: 3191.3 | H5: TRUE
A6: Grillo | B6: 127 | C6: FALSE | F6: Anualidad tarjeta | G6: 600 | H6: TRUE
F7: Gastos varios | G7: 2422.1 | H7: TRUE
F8: Alimentos | G8: 165 | H8: TRUE
F9: Compra | G9: 6464.75 | H9: TRUE
F10: Reyes | G10: 2012.65 | H10: TRUE
H11: FALSE
H12: FALSE
H13: FALSE
H14: FALSE
H15: FALSE
H16: FALSE
H17: FALSE
H18: FALSE
H19: FALSE
H20: FALSE
H21: FALSE
H22: FALSE
... H43: FALSE
A96: Total | B96: =SUM(B2:B95) -> 1067.32 | F96: Total | G96: =SUM(G2:G49) -> 30161.3
A97: Por Pagar | B97: =SUMIF(C2:C95, false, B2:B95) -> 1067.32 | F97: Por Pagar | G97: =SUMIF(H2:H64, false, G2:G64) -> 0
A105: Historico
A106: Ago-Sept | F106: Uber eats | G106: 321.69 | H106: TRUE
A107: La comer 17/08 | B107: 3452.76 | C107: TRUE | F107: Uber eats | G107: 30 | H107: TRUE | J107: Sanborns | K107: 36 | L107: TRUE | N107: Mercado | O107: 184 | P107: TRUE
A108: Casa Toño | B108: =576.56+60 -> 636.56 | C108: FALSE | F108: La comer de valle | G108: 602.17 | H108: TRUE | J108: Soriana | K108: 595.6 | L108: TRUE | N108: Santa clara | O108: 100 | P108: TRUE
A109: Oxxo Caseta Oacalco | B109: 157 | C109: TRUE | F109: Oxxo | G109: 79 | H109: TRUE | J109: Santa Clara | K109: 274 | L109: TRUE | N109: Garat | O109: 210 | P109: TRUE
A110: Panda Express | B110: 875 | C110: TRUE | F110: Los Lalos | G110: 586.3 | H110: TRUE | J110: Semillero | K110: 510.4 | L110: TRUE | N110: Los Lalos | O110: 577.5 | P110: TRUE
A111: Grillo | B111: 78 | C111: TRUE | F111: Uber | G111: 109.98 | H111: TRUE | J111: Tierra GARAT | K111: 125 | L111: TRUE | N111: La comer | O111: 3224.3 | P111: TRUE
A112: Desayuno | B112: 234.28 | C112: TRUE | F112: Toks | G112: 535.7 | H112: TRUE | J112: X | K112: 67 | L112: TRUE | N112: Grillo | O112: 48 | P112: TRUE
A113: Cafe | B113: 54 | C113: TRUE | F113: Soriana | G113: 351 | H113: TRUE | J113: Grillo | K113: 113 | L113: TRUE | N113: Uber eats | O113: 50 | P113: TRUE
A114: Starbucks | B114: 400 | C114: TRUE | F114: esperanza | G114: 178 | H114: TRUE | J114: Grillo | K114: 106 | L114: TRUE | N114: Uber eats | O114: 560.43 | P114: TRUE
A115: Uber | B115: 85.7 | C115: TRUE | F115: McDonalds | G115: 579 | H115: TRUE | J115: La comer | K115: 4043.73 | L115: TRUE | N115: Grillo | O115: 68 | P115: TRUE
A116: H&M | B116: 1810 | C116: TRUE | F116: Tommy Pizza | G116: 421 | H116: TRUE | J116: Pasteles CSM | K116: 120 | L116: TRUE | N116: Rincon de ade | O116: 240 | P116: TRUE
A117: Esperanza | B117: 146 | C117: TRUE | F117: Carrito oaxaca | G117: 254 | H117: TRUE | J117: Pasteles CSM | K117: 80 | L117: TRUE | N117: Iguana | O117: 71 | P117: TRUE
A118: Santa Clara | B118: 212 | C118: TRUE | F118: Grillo | G118: 50 | H118: TRUE | J118: Santa Clara | K118: 186 | L118: TRUE | N118: Soriana | O118: 382.27 | P118: TRUE
A119: Uber Chillis | B119: 399.6 | C119: TRUE | F119: Mac donalds | G119: 85 | H119: TRUE | J119: Madraje | K119: 206.8 | L119: TRUE | N119: Los Lalos | O119: 479.6 | P119: TRUE
...

Sheet Gastos Generales
A1: Concepto | B1: Monto | C1: Pagado | D1: Tarjeta Usada
A2: Zapatos Leander | B2: 670 | C2: TRUE | D2: Palacio de Hierro
A3: Heladeria Roxy | B3: 392.7 | C3: TRUE | D3: AMEX
A4: Gasolina | B4: 1210.24 | C4: TRUE | D4: 2Now Gastos
A5: Amazon | B5: 237.2 | C5: FALSE | D5: 2Now Gastos
A6: Amazon bomba | B6: 1499 | C6: FALSE | D6: 2Now Gastos
A7: Labial Dalia | B7: 920 | C7: TRUE | D7: Liverpool
A8: Peluqueria Lean | B8: 215 | C8: TRUE | D8: Liverpool
A9: Amazon | B9: 392 | C9: TRUE | D9: AMEX
A10: Amazon | B10: 359 | C10: TRUE | D10: AMEX
A11: Amazon | B11: 329.69 | C11: TRUE | D11: AMEX
A12: Amazon | B12: 325.59 | C12: TRUE | D12: AMEX
A13: Playstation | B13: 246.22 | C13: TRUE | D13: AMEX
... A25: Natacion | B25: 3000 | C25: FALSE | D25: Uala Credito
H28: =B22+B21 -> 1978
H30: =(H28*0.1)/365 -> 0.54191781
H31: =H30*22 -> 11.922192
B82: Total Gastado | C82: Total por pagar
A83: AMEX | B83: =SUMIF(D$2:D78,A83,B$2:B78) -> 3984.82 | C83: =SUMIFS(B$2:B78,C$2:C78,false,D$2:D78,A83) -> 0
A84: 2Now Gastos | B84: =SUMIF(D$2:D79,A84,B$2:B79) -> 2946.44 | C84: =SUMIFS(B$2:B79,C$2:C79,false,D$2:D79,A84) -> 1736.2
A85: Liverpool | B85: =SUMIF(D$2:D80,A85,B$2:B80) -> 1135 | C85: =SUMIFS(B$2:B80,C$2:C80,false,D$2:D80,A85) -> 0
A86: Palacio de Hierro | B86: =SUMIF(D$2:D81,A86,B$2:B81) -> 670 | C86: =SUMIFS(B$2:B81,C$2:C81,false,D$2:D81,A86) -> 0
A87: Uala Credito | B87: =SUMIF(D$2:D82,A87,B$2:B82) -> 8315 | C87: =SUMIFS(B$2:B82,C$2:C82,false,D$2:D82,A87) -> 8315
A88: Nu | B88: =SUMIF(D$2:D83,A88,B$2:B83) -> 0 | C88: =SUMIFS(B$2:B83,C$2:C83,false,D$2:D83,A88) -> 0
A89: Costco | B89: =SUMIF(D$2:D84,A89,B$2:B84) -> 18945 | C89: =SUMIFS(B$2:B84,C$2:C84,false,D$2:D84,A89) -> 0
A92: Historico | N92: Historico AMEX
A93: Ago-Sept | E93: Sept-Oct | I93: Dic-Ene | N93: Ferreteria Fusibles | O93: 576 | P93: TRUE | R93: Historico
A94: Cafe la comer | B94: 129 | C94: TRUE | E94: Ihop | F94: 1012 | G94: TRUE | I94: La comer | J94: 3004.52 | K94: TRUE | L94: 2Now Gastos | N94: La comer cafe | O94: 56 | P94: TRUE | R94: uber | S94: 47.31 | T94: TRUE | U94: 2Now Gastos
A95: Uber | B95: 126.21 | C95: TRUE | E95: Dairy Queen | F95: 148 | G95: TRUE | I95: Uber | J95: 49.95 | K95: TRUE | L95: 2Now Gastos | N95: La comer Cafe | O95: 129 | P95: TRUE | R95: Farmacia | S95: 193 | T95: TRUE | U95: 2Now Gastos
A96: Rappi | B96: 207.8 | C96: TRUE | E96: Gasolina | F96: 1176.13 | G96: TRUE | I96: Flores Dalia | J96: 820.65 | K96: TRUE | L96: 2Now Gastos | N96: Oxxo | O96: 47 | P96: TRUE | R96: uber | S96: 64.09 | T96: TRUE | U96: 2Now Gastos
A97: Uber | B97: 126.21 | C97: TRUE | E97: Oxxo | F97: 116 | G97: TRUE | I97: Gasolina | J97: 1023.72 | K97: TRUE | L97: 2Now Gastos | N97: Petco | O97: 715 | P97: TRUE | R97: Motrin y alasol | S97: 359 | T97: TRUE | U97: 2Now Gastos
A98: Lumen | B98: 200 | C98: TRUE | E98: Fotos visa | F98: 240 | G98: TRUE | I98: Santa Clara | J98: 482 | K98: TRUE | L98: 2Now Gastos | N98: Mantenimiento Auto | O98: 4500 | P98: TRUE | R98: Cremas neutrogena | S98: 421.2 | T98: TRUE | U98: 2Now Gastos
A99: Petco | B99: 357.5 | C99: TRUE | E99: Waldos | F99: 147.94 | G99: TRUE | I99: Amazon | J99: 333 | K99: TRUE | L99: 2Now Gastos | N99: Sfera | O99: 827 | P99: TRUE | R99: Moneypool | S99: 31.17 | T99: TRUE | U99: 2Now Gastos
A100: Grillo | B100: 32 | C100: TRUE | E100: uber | F100: 57.94 | G100: TRUE | I100: Uber | J100: 99.96 | K100: TRUE | L100: 2Now Gastos | N100: Zara | O100: 1665 | P100: TRUE | R100: Lumen | S100: 6.5 | T100: TRUE | U100: 2Now Gastos
A101: Grillo | B101: 107 | C101: TRUE | E101: Uber | F101: 240.81 | G101: TRUE | I101: Uber | J101: 89.94 | K101: TRUE | L101: 2Now Gastos | N101: Gap | O101: 319.2 | P101: TRUE | R101: Lumen | S101: 399.9 | T101: TRUE | U101: 2Now Gastos
A102: Cafe San Pedro | B102: 266 | C102: TRUE | E102: Veterinario | F102: 405 | G102: TRUE | I102: Uber | J102: 99.97 | K102: TRUE | L102: 2Now Gastos | N102: Tiendita olinca | O102: 100 | P102: TRUE | R102: Tempra | S102: 225.5 | T102: TRUE | U102: 2Now Gastos
A103: Pediasure e Ibuprofeno | B103: 293.5 | C103: TRUE | E103: Grillo | F103: 40 | G103: TRUE | I103: Uber | J103: 79.97 | K103: TRUE | L103: 2Now Gastos | N103: Cinnabon | O103: 375 | P103: TRUE | R103: Gasolina | S103: 1256.82 | T103: TRUE | U103: 2Now Gastos
A104: Maison Kayser | B104: 251 | C104: TRUE | E104: Antibiotico | F104: 428 | G104: TRUE | I104: Uber | J104: 368.71 | K104: TRUE | L104: 2Now Gastos | N104: Starbucks | O104: 111 | P104: TRUE | R104: Verificacion | S104: 666 | T104: TRUE | U104: 2Now Gastos
A105: Maison Kayser | B105: 58.8 | C105: TRUE | E105: Oxxo | F105: 10 | G105: TRUE | I105: Gasolina | J105: 1247.65 | K105: TRUE | L105: 2Now Gastos | N105: Wifi Avion | O105: 151.03 | P105: TRUE | R105: Rappi | S105: 313.18 | T105: TRUE | U105: AMEX
A106: La comer | B106: 142 | C106: TRUE | E106: Uber | F106: 119.37 | G106: TRUE | I106: Rappi | J106: =333.9 -> 333.9 | K106: TRUE | L106: 2Now Gastos | N106: Inscripcion Gimnasia | O106: 2500 | P106: TRUE | R106: Tierra Garat | S106: 76 | T106: TRUE | U106: AMEX
...

Sheet Gastos WE
A1: Gastos Programados | C1: Pagado | E1: Otros Gastos | F1: Monto | G1: Pagado | H1: Fecha
A2: sports world | B2: 5005 | C2: TRUE | G2: TRUE
A3: Totalplay | B3: 1190 | C3: TRUE | G3: FALSE
A4: Digital ocean | B4: =IFERROR(__xludf.DUMMYFUNCTION("GOOGLEFINANCE(""CURRENCY:USDMXN"")*6"),103.30260000000001) -> 103.3026 | C4: TRUE | G4: FALSE
A5: Telefonica | B5: 940 | C5: TRUE | G5: FALSE
A6: Claude | B6: =IFERROR(__xludf.DUMMYFUNCTION("GOOGLEFINANCE(""CURRENCY:USDMXN"")*20"),344.34200000000004) -> 344.342 | C6: TRUE | G6: FALSE
A7: HBO Max | B7: 199 | C7: TRUE | G7: FALSE
A8: Electricidad | B8: 1171 | C8: TRUE | G8: FALSE
A9: Agua | B9: 349 | C9: TRUE
C10: FALSE
C11: FALSE
C12: FALSE
C13: FALSE
C14: FALSE
C15: FALSE
C16: FALSE
C17: FALSE
C18: FALSE
C19: FALSE
C20: FALSE
C21: FALSE
C22: FALSE
C64: Por Pagar | G64: Por Pagar
B65: =SUM(B2:B32) -> 9301.6446 | C65: =SUMIF(C2:C34, false, B2:B34) -> 0 | F65: =SUM(F2:F63) -> 0 | G65: =SUMIF(G2:G63, false, F2:F63) -> 0
F68: =F65+B65 -> 9301.6446
A76: Historico
A77: Hasta 17 Nov | E77: Hasta 17 Ene
A78: Olinca | B78: 17280 | C78: TRUE | E78: Portacables | F78: =1040.93-F94-F95 -> 249 | G78: TRUE | H78: 45982
A79: Bicicletas | B79: 8598 | C79: TRUE | E79: PortaPasteles | F79: 277 | G79: TRUE | H79: 45994
A80: Olinca (Uniformes, licencias) | B80: 3300 | C80: TRUE | E80: Accesorios pasteles | F80: 279 | G80: TRUE | H80: 45994
A81: Olinca (Uniformes, licencias) | B81: 3300 | C81: TRUE | E81: Cera | F81: =119*2 -> 238 | G81: TRUE | H81: 45992
A82: Avion Tijuana | B82: 2899.58 | C82: TRUE | E82: adaptadores micro-usb | F82: 115.3 | G82: TRUE | H82: 45992
A83: Podologia | B83: 2886 | C83: TRUE | E83: Aceite y desmaquillante | F83: 249.85 | G83: TRUE | H83: 45992
A84: IKEA | B84: 2555 | C84: TRUE | E84: Pastel Lena | F84: 1580 | G84: TRUE | H84: 45993
A85: Zara | B85: 2127 | C85: TRUE | E85: Comida Cine | F85: 680 | G85: TRUE | H85: 45991
A86: Toys R Us Perisur | B86: 2067 | C86: TRUE | E86: Posada Suizo | F86: 1558.5 | G86: TRUE | H86: 45992
A87: Lefties | B87: 1942 | C87: TRUE | E87: La comer | F87: 90 | G87: TRUE | H87: 45992
A88: Apple | B88: 1599 | C88: TRUE | E88: Boletos Cine | F88: 333 | G88: TRUE | H88: 45991
A89: Gas | B89: 1500 | C89: TRUE | E89: Juguetron | F89: 45 | G89: TRUE | H89: 45991
A90: Spa | B90: 1198 | C90: TRUE | E90: Ferreteria | F90: 144 | G90: TRUE | H90: 45990
...

Sheet Gastos Medicos Menores
A1: Medicamentos y Consultas | C1: Facturado | D1: Subido a Risco | E1: Reembolsado | F1: Pagado | G1: Tarjeta Usada | H1: Suma A reembolsar
A2: Medicinas Dalia | B2: 1044 | C2: Si | D2: Si | E2: Si | F2: TRUE | G2: 2Now Gastos | H2: =B2*0.9 -> 939.6
A3: Ginecologa | B3: 1500 | C3: Si | D3: Si | E3: Si | F3: TRUE | G3: 2Now Gastos | H3: =B3*0.9 -> 1350
A4: Vacuna Alfredo | B4: 2500 | C4: Si | D4: Si | E4: Si | F4: TRUE | G4: 2Now Gastos | H4: =B4*0.9 -> 2250
A5: Alergologo Leander | B5: 1500 | C5: Si | D5: Si | E5: Si | F5: TRUE | G5: 2Now Gastos | H5: =B5*0.9 -> 1350
A6: Blaxitec | B6: 476 | C6: Si | D6: Si | E6: Si | F6: TRUE | G6: 2Now Gastos | H6: =B6*0.9 -> 428.4
A7: Medicinas Alfredo | B7: 593 | C7: Si | D7: Si | E7: Si | F7: TRUE | G7: 2Now Gastos | H7: =B7*0.9 -> 533.7
A8: Podologa | B8: 1986 | C8: Si | F8: TRUE | G8: 2Now Gastos | H8: =B8*0.9 -> 1787.4
A9: Vacuna Lena | B9: 1700 | C9: Si | D9: Si | E9: Si | F9: TRUE | G9: 2Now Gastos | H9: =B9*0.9 -> 1530
A10: Laser Onicomicosis | B10: 6800 | C10: Si | D10: Si | E10: Si | F10: TRUE | G10: AMEX | H10: =B10*0.9 -> 6120
A11: Estudios Lena y Leander | B11: =3187+2583.99 -> 5770.99 | C11: Si | D11: Si | E11: Si | F11: TRUE | G11: AMEX | H11: =B11*0.9 -> 5193.891
A12: Ferricol | B12: 436 | C12: Si | F12: TRUE | G12: 2Now Gastos | H12: =B12*0.9 -> 392.4
A13: Vacuna Alfredo | B13: 2500 | C13: Si | D13: Si | E13: Si | F13: TRUE | G13: 2Now Gastos | H13: =B13*0.9 -> 2250
A14: Radiografia Chopo | B14: 594.3 | F14: TRUE | G14: AMEX | H14: =B14*0.9 -> 534.87
A15: Radiografia Lab Polanco | B15: 913 | C15: Si | D15: Si | E15: Si | F15: TRUE | G15: AMEX | H15: =B15*0.9 -> 821.7
A16: Radiografias StarMedica | B16: 3261.21 | C16: Si | D16: Si | E16: Si | F16: TRUE | G16: AMEX | H16: =B16*0.9 -> 2935.089
A17: Crema | B17: 350 | C17: Si | F17: TRUE | G17: AMEX | H17: =B17*0.9 -> 315
A18: Consulta Alergologo | B18: 1500 | C18: Si | D18: Si | E18: Si | F18: TRUE | G18: AMEX | H18: =B18*0.9 -> 1350
A19: Combivent Rescate | B19: 1236 | C19: Si | D19: Si | E19: Si | F19: TRUE | G19: 2Now Gastos | H19: =B19*0.9 -> 1112.4
A20: Medicinas nebulizador | B20: 1183 | C20: Si | D20: Si | E20: Si | F20: TRUE | G20: 2Now Gastos | H20: =B20*0.9 -> 1064.7
A21: Antibiotico | B21: 748 | C21: Si | F21: TRUE | G21: AMEX | H21: =B21*0.9 -> 673.2
A22: Vacuna Varicela y Sarampion | B22: 2600 | C22: Si | D22: Si | E22: Si | F22: TRUE | G22: 2Now Gastos | H22: =B22*0.9 -> 2340
A23: Vacuna Varicela | B23: 1650 | C23: Si | D23: Si | E23: Si | F23: TRUE | G23: 2Now Gastos | H23: =B23*0.9 -> 1485
A24: Podologa | B24: 538 | C24: Si | F24: TRUE | G24: 2Now Gastos | H24: =B24*0.9 -> 484.2
A25: Medicinas | B25: 1028 | C25: Si | F25: TRUE | G25: AMEX | H25: =B25*0.9 -> 925.2
A26: Antibiotico | B26: 461 | C26: Si | F26: TRUE | G26: AMEX | H26: =B26*0.9 -> 414.9
A27: Medicinas | B27: 456 | C27: Si | F27: TRUE | G27: 2Now Gastos | H27: =B27*0.9 -> 410.4
A28: Vacuna Alfredo | B28: 2500 | C28: Si | D28: Si | E28: Si | F28: TRUE | G28: AMEX | H28: =B28*0.9 -> 2250
A29: Cita psicologa | B29: 600 | F29: TRUE | G29: HSBC World elite | H29: =B29*0.9 -> 540
A30: Podologa | B30: 538 | C30: Si | D30: Si | E30: Si | F30: TRUE | G30: AMEX | H30: =B30*0.9 -> 484.2
A31: Pulmicort y kits | B31: =682+170 -> 852 | C31: Si | D31: Si | E31: Si | F31: TRUE | G31: 2Now Gastos | H31: =B31*0.9 -> 766.8
A32: Medicinas garganta | B32: 2096.5 | C32: Si | D32: Si | E32: Si | F32: TRUE | G32: AMEX | H32: =B32*0.9 -> 1886.85
A33: Ferricol | B33: 436 | F33: TRUE | G33: AMEX | H33: =B33*0.9 -> 392.4
A34: Vannair | B34: 1219 | C34: Si | D34: Si | E34: Si | F34: TRUE | G34: AMEX | H34: =B34*0.9 -> 1097.1
A35: Podologia Productos | B35: 359 | C35: Si | F35: TRUE | G35: AMEX | H35: =B35*0.9 -> 323.1
A36: Vacuna Alfredo | B36: 2500 | C36: Si | D36: Si | F36: TRUE | G36: AMEX | H36: =B36*0.9 -> 2250
A37: Vacuna Lena | B37: 1700 | C37: Si | D37: Si | F37: TRUE | G37: AMEX | H37: =B37*0.9 -> 1530
A38: Medicinas ojo Lena | B38: 2291 | C38: Si | D38: Si | F38: TRUE | G38: AMEX | H38: =B38*0.9 -> 2061.9
A39: Gastos Extra HIP | B39: 2577.17 | C39: Si | F39: TRUE | G39: AMEX | H39: =B39*0.9 -> 2319.453
A40: Oftalmologa Lena | B40: 1300 | C40: Si | F40: TRUE | G40: 2Now Gastos | H40: =B40*0.9 -> 1170
...

Sheet Gastos Medicos Mayores
A1: Concepto | B1: Monto | C1: Facturado | D1: Pagado | E1: Reembolso solicitado | F1: Reembolsado | G1: Tarjeta
A2: 4 Sesiones Terapia | B2: 4496.54 | C2: TRUE | D2: TRUE
A3: 1 Sesion Terapia | B3: 1124.13 | C3: TRUE | D3: TRUE
A6: Neumonia Leander
A7: Medicinas nebulizacion | B7: 1046.79 | C7: TRUE | D7: TRUE | E7: FALSE | F7: FALSE | G7: AMEX | H7: =B7*0.9 -> 942.111
A8: Consulta neumologa | B8: 1300 | C8: TRUE | D8: TRUE | E8: FALSE | F8: FALSE | G8: AMEX | H8: =B8*0.9 -> 1170
A9: Medicinas mantenimiento (Vannair, allegra, esteroide) | B9: 3507 | C9: TRUE | D9: TRUE | E9: FALSE | F9: FALSE | G9: 2Now Gastos | H9: =B9*0.9 -> 3156.3
A10: Medicinas Nuemologa | B10: 6263.5 | C10: TRUE | D10: TRUE | E10: FALSE | F10: FALSE | G10: AMEX | H10: =B10*0.9 -> 5637.15
A11: Consulta 2 neumologa | B11: 1300 | C11: FALSE | D11: TRUE | E11: FALSE | F11: FALSE | G11: AMEX | H11: =B11*0.9 -> 1170
A12: Medicinas 2 Neumologa | B12: 2081 | C12: TRUE | D12: TRUE | E12: FALSE | F12: FALSE | G12: AMEX | H12: =B12*0.9 -> 1872.9
A13: Medicinas 2 Neumologa | B13: 754 | C13: TRUE | D13: FALSE | E13: FALSE | F13: FALSE | G13: HSBC World elite | H13: =B13*0.9 -> 678.6
A14: Consulta 3 Neumologa | B14: 1400 | C14: FALSE | D14: FALSE | E14: FALSE | F14: FALSE | G14: AMEX | H14: =B14*0.9 -> 1260
A15: Medicinas 2 Neumologa | B15: 3802 | C15: FALSE | D15: FALSE | E15: FALSE | F15: FALSE | G15: 2Now Gastos | H15: =B15*0.9 -> 3421.8
J16: =SUM(B7:B15) -> 21454.29
A17: Inmunologia Leander
A18: Pruebas alergia Leander | B18: 4000 | C18: TRUE | D18: TRUE | E18: FALSE | F18: FALSE | G18: AMEX | H18: =B18*0.9 -> 3600
A19: Vacuna Leander | B19: 1700 | C19: TRUE | D19: TRUE | E19: FALSE | F19: FALSE | G19: AMEX | H19: =B19*0.9 -> 1530
A20: Vacuna Leander | B20: 1700 | C20: TRUE | D20: TRUE | E20: FALSE | F20: FALSE | G20: AMEX | H20: =B20*0.9 -> 1530
C36: Total Gastado | D36: Total por pagar
B37: AMEX | C37: =SUMIF(G$2:G32,B37,B$2:B32) -> 20791.29 | D37: =SUMIFS(B$2:B32,D$2:D32,false,G$2:G32,B37) -> 1400
B38: 2Now Gastos | C38: =SUMIF(G$2:G33,B38,B$2:B33) -> 7309 | D38: =SUMIFS(B$2:B33,D$2:D33,false,G$2:G33,B38) -> 3802

Sheet Totales y Transferencias
A1: Column 1 | B1: CLABE | C1: Referencia en deposito | D1: Total Mensual | E1: Total quincenal | F1: Programada | G1: 16/02/2025 | H1: 01/03/2025 | I1: 14/03/2025 | J1: 31/03/2025 | K1: 15/04/2025 | L1: 30/04/2025 | M1: 15/05/2025 | N1: 31/05/2025 | O1: 15/06/2025 | P1: 30/06/2025 | Q1: 15/07/2025 | R1: 31/07/25 | S1: 15/08/25 | T1: 31/08/25
A2: HSBC Flexible | B2: {=INDEX(Table3[CLABE], MATCH(A2, Table3[Nombre cuenta], 0))} -> 021180065930525793 | C2: {=INDEX(Table3[Codigo Referencia], MATCH(A2, Table3[Nombre cuenta], 0))} -> 0000011 | D2: =SUMIF(Actual!$I$3:$I$89, A2, Actual!$B$3:$B$89) -> 39300 | E2: =SUMIF(Actual!$I$3:$I$89, A2, Actual!$C$3:$C$89) -> 19650 | F2: TRUE | G2: TRUE | H2: TRUE | I2: TRUE | J2: TRUE | K2: TRUE | L2: TRUE | M2: TRUE | N2: FALSE | O2: FALSE | P2: TRUE | Q2: TRUE | R2: TRUE | S2: TRUE | T2: TRUE
A3: Uala | B3: {=INDEX(Table3[CLABE], MATCH(A3, Table3[Nombre cuenta], 0))} -> 138580000023894928 | C3: {=INDEX(Table3[Codigo Referencia], MATCH(A3, Table3[Nombre cuenta], 0))} -> 0000014 | D3: =SUMIF(Actual!$I$3:$I$89, A3, Actual!$B$3:$B$89) -> 32800 | E3: =SUMIF(Actual!$I$3:$I$89, A3, Actual!$C$3:$C$89) -> 16400 | F3: TRUE | G3: TRUE | H3: TRUE | I3: TRUE | J3: TRUE | K3: TRUE | L3: TRUE | M3: TRUE | N3: TRUE | O3: TRUE | P3: TRUE | Q3: TRUE | R3: TRUE | S3: TRUE | T3: TRUE
A4: Nu Cajita Hogar | B4: {=INDEX(Table3[CLABE], MATCH(A4, Table3[Nombre cuenta], 0))} -> 638180000177404193 | C4: {=INDEX(Table3[Codigo Referencia], MATCH(A4, Table3[Nombre cuenta], 0))} -> 0000016 | D4: =SUMIF(Actual!$I$3:$I$89, A4, Actual!$B$3:$B$89) -> 23200 | E4: =SUMIF(Actual!$I$3:$I$89, A4, Actual!$C$3:$C$89) -> 11600 | F4: TRUE | G4: TRUE | H4: TRUE | I4: TRUE | J4: TRUE | K4: TRUE | L4: TRUE | M4: TRUE | N4: TRUE | O4: TRUE | P4: TRUE | Q4: TRUE | R4: TRUE | S4: TRUE | T4: TRUE
A5: Nu Cajita Auto | B5: {=INDEX(Table3[CLABE], MATCH(A5, Table3[Nombre cuenta], 0))} -> 638180000177404193 | C5: {=INDEX(Table3[Codigo Referencia], MATCH(A5, Table3[Nombre cuenta], 0))} -> 0000012 | D5: =SUMIF(Actual!$I$3:$I$89, A5, Actual!$B$3:$B$89) -> 17500 | E5: =SUMIF(Actual!$I$3:$I$89, A5, Actual!$C$3:$C$89) -> 8750 | F5: FALSE | G5: TRUE | H5: TRUE | I5: TRUE | J5: TRUE | K5: TRUE | L5: TRUE | M5: TRUE | N5: TRUE | O5: TRUE | P5: TRUE | Q5: TRUE | R5: TRUE | S5: TRUE | T5: TRUE
A6: HSBC | B6: {=INDEX(Table3[CLABE], MATCH(A6, Table3[Nombre cuenta], 0))} -> 021180040690613986 | C6: {=INDEX(Table3[Codigo Referencia], MATCH(A6, Table3[Nombre cuenta], 0))} -> 0000001 | D6: =SUMIF(Actual!$I$3:$I$89, A6, Actual!$B$3:$B$89) -> 10000 | E6: =SUMIF(Actual!$I$3:$I$89, A6, Actual!$C$3:$C$89) -> 5000 | F6: FALSE | G6: TRUE | H6: TRUE | I6: TRUE | J6: TRUE | K6: TRUE | L6: TRUE | M6: TRUE | N6: FALSE | O6: FALSE | P6: FALSE | Q6: FALSE | R6: FALSE | S6: FALSE | T6: FALSE
A7: Nu Cajita Gastos | B7: {=INDEX(Table3[CLABE], MATCH(A7, Table3[Nombre cuenta], 0))} -> 638180000177404193 | C7: {=INDEX(Table3[Codigo Referencia], MATCH(A7, Table3[Nombre cuenta], 0))} -> 0000013 | D7: =SUMIF(Actual!$I$3:$I$89, A7, Actual!$B$3:$B$89) -> 9900 | E7: =SUMIF(Actual!$I$3:$I$89, A7, Actual!$C$3:$C$89) -> 4950 | F7: FALSE | G7: TRUE | H7: TRUE | I7: TRUE | J7: TRUE | K7: TRUE | L7: TRUE | M7: TRUE | N7: TRUE | O7: TRUE | P7: TRUE | Q7: TRUE | R7: TRUE | S7: TRUE | T7: TRUE
A8: Stori Inversion + | B8: {=INDEX(Table3[CLABE], MATCH(A8, Table3[Nombre cuenta], 0))} -> 646180402300057567 | C8: {=INDEX(Table3[Codigo Referencia], MATCH(A8, Table3[Nombre cuenta], 0))} -> 0000015 | D8: =SUMIF(Actual!$I$3:$I$89, A8, Actual!$B$3:$B$89) -> 4500 | E8: =SUMIF(Actual!$I$3:$I$89, A8, Actual!$C$3:$C$89) -> 2250 | F8: FALSE | G8: TRUE | H8: TRUE | I8: TRUE | J8: TRUE | K8: TRUE | L8: TRUE | M8: TRUE | N8: TRUE | O8: TRUE | P8: TRUE | Q8: TRUE | R8: TRUE | S8: TRUE | T8: TRUE
A9: Nu Dalia Debito | B9: {=INDEX(Table3[CLABE], MATCH(A9, Table3[Nombre cuenta], 0))} -> 638180010151893079 | C9: {=INDEX(Table3[Codigo Referencia], MATCH(A9, Table3[Nombre cuenta], 0))} -> 0000004 | D9: =SUMIF(Actual!$I$3:$I$89, A9, Actual!$B$3:$B$89) -> 3700 | E9: =SUMIF(Actual!$I$3:$I$89, A9, Actual!$C$3:$C$89) -> 1850 | F9: FALSE | G9: TRUE | H9: TRUE | I9: TRUE | J9: TRUE | K9: TRUE | L9: TRUE | M9: TRUE | N9: TRUE | O9: TRUE | P9: TRUE | Q9: TRUE | R9: TRUE | S9: TRUE | T9: TRUE
A10: GBM Trading | B10: {=INDEX(Table3[CLABE], MATCH(A10, Table3[Nombre cuenta], 0))} -> 601180400038253515 | C10: {=INDEX(Table3[Codigo Referencia], MATCH(A10, Table3[Nombre cuenta], 0))} -> 0000104 | D10: =SUMIF(Actual!$I$3:$I$89, A10, Actual!$B$3:$B$89) -> 500 | E10: =SUMIF(Actual!$I$3:$I$89, A10, Actual!$C$3:$C$89) -> 250 | F10: FALSE | G10: TRUE | H10: TRUE | I10: TRUE | J10: TRUE | K10: TRUE | L10: FALSE | M10: TRUE | N10: TRUE | O10: TRUE | P10: TRUE | Q10: TRUE | R10: TRUE | S10: TRUE | T10: TRUE
A11: GBM Dolares | B11: {=INDEX(Table3[CLABE], MATCH(A11, Table3[Nombre cuenta], 0))} -> 601180400049499232 | C11: {=INDEX(Table3[Codigo Referencia], MATCH(A11, Table3[Nombre cuenta], 0))} -> 0000103 | D11: =SUMIF(Actual!$I$3:$I$89, A11, Actual!$B$3:$B$89) -> 500 | E11: =SUMIF(Actual!$I$3:$I$89, A11, Actual!$C$3:$C$89) -> 250 | F11: FALSE | G11: TRUE | H11: TRUE | I11: TRUE | J11: TRUE | K11: TRUE | L11: TRUE | M11: TRUE | N11: TRUE | O11: TRUE | P11: TRUE | Q11: TRUE | R11: TRUE | S11: TRUE | T11: TRUE
C14: Total | D14: =SUM(Current_transactions[Total Mensual]) -> 141900 | E14: =SUM(Current_transactions[Total quincenal]) -> 70950 | K14: Mensual | L14: Quincenal
J15: Total | K15: =Actual!B16+Actual!B32+Actual!B40+Actual!B48+Actual!B60+Actual!B77+Actual!B85 -> 141900 | L15: =Actual!C16+Actual!C32+Actual!C40+Actual!C48+Actual!C60+Actual!C85+Actual!C77 -> 70950
D26: =D14+5000 -> 146900 | E26: =E14+5000 -> 75950 | N26: v

Sheet Actual
A1: Kids | Q1: Salario Mensual | R1: Salario Quincenal
Q2: 142000 | R2: =Q2/2 -> 71000
A3: Nombre | B3: Mensual | C3: Quincenal | D3: Es Anual | E3: Costo Anual | F3: Costo Mensual | G3: Comentarios | H3: Cuenta Cargo | I3: Cuenta deposito
A4: Colegiatura Lena | B4: =CEILING(F4,100) -> 15800 | C4: =CEILING(B4/2, 10) -> 7900 | D4: =IF(E4>0, true) -> FALSE | F4: 15770 | H4: HSBC World elite | I4: Uala | P4: Objetivos Ahorro
A5: Colegiatura Leander | B5: =CEILING(F5,100) -> 8000 | C5: =CEILING(B5/2, 10) -> 4000 | D5: =IF(E5>0, true) -> FALSE | F5: 7915 | H5: Uala | I5: Uala | P5: Largo Plazo (11%) | Q5: =Q2*0.11 -> 15620 | R5: =Q5/2 -> 7810
A6: Horario Extendido Leander | B6: =CEILING(F6,100) -> 2200 | C6: =CEILING(B6/2, 10) -> 1100 | D6: =IF(E6>0, true) -> FALSE | F6: 2200 | G6: 2 dias por semana | H6: Uala | I6: Uala | P6: Corto Plazo (9%) | Q6: =Q2*0.09 -> 12780 | R6: =Q6/2 -> 6390
A7: Clases de aleman | B7: =CEILING(F7,100) -> 2000 | C7: =CEILING(B7/2, 10) -> 1000 | D7: =IF(E7>0, true) -> FALSE | F7: 2000 | G7: 4 clases al mes (4 Mi por mes) | H7: HSBC World elite | I7: Uala
A8: Inscripcion Lena | B8: =CEILING(F8,100) -> 1700 | C8: =CEILING(B8/2, 10) -> 850 | D8: =IF(E8>0, true) -> TRUE | E8: 19500 | F8: =E8/12 -> 1625 | G8: Al menos 50% de la siguiente inscripcion | H8: HSBC World elite | I8: Stori Inversion +
A9: Natacion Lena | B9: =CEILING(F9,100) -> 1300 | C9: =CEILING(B9/2, 10) -> 650 | D9: =IF(E9>0, true) -> FALSE | F9: 1270 | G9: =Deuda!A23Vuelo -> #NAME? | H9: HSBC World elite | I9: Uala
A10: Ballet | B10: =CEILING(F10,100) -> 1200 | C10: =CEILING(B10/2, 10) -> 600 | D10: =IF(E10>0, true) -> FALSE | F10: 1200 | H10: Nu Dalia Debito | I10: Nu Dalia Debito
A11: Natacion Leander | B11: =CEILING(F11,100) -> 1300 | C11: =CEILING(B11/2, 10) -> 650 | D11: =IF(E11>0, true) -> FALSE | F11: 1270 | H11: HSBC World elite | I11: Uala
A12: Lena Yoga | B12: =CEILING(F12,100) -> 1100 | C12: =CEILING(B12/2, 10) -> 550 | D12: =IF(E12>0, true) -> FALSE | F12: =CEILING(1100, 10) -> 1100 | H12: HSBC World elite | I12: Uala
A13: Lena Robotica | B13: =CEILING(F13,100) -> 1100 | C13: =CEILING(B13/2, 10) -> 550 | D13: =IF(E13>0, true) -> FALSE | F13: 1100 | H13: HSBC World elite | I13: Uala
A14: Inscripcion Leander | B14: =CEILING(F14,100) -> 800 | C14: =CEILING(B14/2, 10) -> 400 | D14: =IF(E14>0, true) -> TRUE | E14: =9500 -> 9500 | F14: =E14/12 -> 791.66667 | H14: Uala | I14: Stori Inversion +
A16: Total | B16: =SUM(B3:B15) -> 36500 | C16: =SUM(C3:C15) -> 18250 | F16: =SUM(F3:F15) -> 36241.667 | L16: =E8+E23+E24+E26+E29+E28+E54+E55+E57+E73+E14 -> 62839
A18: Suscripciones
A20: Nombre | B20: Mensual | C20: Quincenal | D20: Es Anual | H20: Cuenta Cargo | I20: Cuenta Deposito
A21: Sports World | B21: =CEILING(F21,100) -> 3900 | C21: =CEILING(B21/2, 10) -> 1950 | D21: =IF(E21>0, true) -> FALSE | F21: 3850 | H21: HSBC World elite | I21: Nu Cajita Gastos
A22: Netflix | B22: =CEILING(F22,100) -> 400 | C22: =CEILING(B22/2, 10) -> 200 | D22: =IF(E22>0, true) -> FALSE | F22: 350 | H22: 2Now Gastos | I22: Nu Cajita Gastos
A23: NFL game pass | B23: =CEILING(F23,100) -> 300 | C23: =CEILING(B23/2, 10) -> 150 | D23: =IF(E23>0, true) -> TRUE | E23: 3300 | F23: =E23/12 -> 275 | H23: HSBC World elite | I23: Stori Inversion +
A24: Disney | B24: =CEILING(F24,100) -> 200 | C24: =CEILING(B24/2, 10) -> 100 | D24: =IF(E24>0, true) -> TRUE | E24: 2400 | F24: =E24/12 -> 200 | H24: 2Now Gastos | I24: Nu Cajita Gastos
A25: Max | B25: =CEILING(F25,100) -> 200 | C25: =CEILING(B25/2, 10) -> 100 | D25: =IF(E25>0, true) -> FALSE | F25: 199 | H25: 2Now Gastos | I25: Nu Cajita Gastos
A26: Spotify | B26: =CEILING(F26,100) -> 200 | C26: =CEILING(B26/2, 10) -> 100 | D26: =IF(E26>0, true) -> TRUE | E26: 1990 | F26: =E26/12 -> 165.83333 | H26: HSBC World elite | I26: Stori Inversion +
A27: Digital Ocean | B27: =CEILING(F27,100) -> 200 | C27: =CEILING(B27/2, 10) -> 100 | D27: =IF(E27>0, true) -> FALSE | F27: 130 | H27: HSBC World elite | I27: Nu Cajita Gastos
A28: Prime | B28: =CEILING(F28,100) -> 100 | C28: =CEILING(B28/2, 10) -> 50 | D28: =IF(E28>0, true) -> TRUE | E28: 899 | F28: =E28/12 -> 74.916667 | H28: HSBC World elite | I28: Stori Inversion +
A29: Uber one | B29: =CEILING(F29,100) -> 100 | C29: =CEILING(B29/2, 10) -> 50 | D29: =IF(E29>0, true) -> TRUE | E29: 750 | F29: =E29/12 -> 62.5 | H29: HSBC World elite | I29: Stori Inversion +
A30: Frontend masters | B30: =CEILING(F30,100) -> 0 | C30: =CEILING(B30/2, 10) -> 0 | D30: =IF(E30>0, true) -> FALSE | H30: HSBC World elite | I30: Nu Cajita Gastos
A32: Total | B32: =SUM(B21:B30) -> 5600 | C32: =SUM(C21:C30) -> 2800 | F32: =SUM(F21:F30) -> 5307.25
A34: Telecomunicaciones
A35: Nombre | B35: Mensual | C35: Quincenal | D35: Es Anual | H35: Cuenta Cargo | I35: Cuenta Deposito
A36: Totalplay (Internet + TV) | B36: =CEILING(F36,100) -> 1400 | C36: =CEILING(B36/2, 10) -> 700 | D36: =IF(E36>0, true) -> FALSE | F36: 1399 | H36: 2Now Hogar | I36: Nu Cajita Hogar
A37: Movistar Dalia | B37: =CEILING(F37,100) -> 500 | C37: =CEILING(B37/2, 10) -> 250 | D37: =IF(E37>0, true) -> FALSE | F37: 500 | H37: 2Now Gastos | I37: Nu Cajita Gastos
A38: Movistar Alfredo | B38: =CEILING(F38,100) -> 500 | C38: =CEILING(B38/2, 10) -> 250 | D38: =IF(E38>0, true) -> FALSE | F38: 439 | H38: 2Now Gastos | I38: Nu Cajita Gastos
A40: Total | B40: =SUM(B36:B39) -> 2400 | C40: =SUM(C36:C39) -> 1200 | F40: =SUM(F36:F39) -> 2338
A42: Ahorro
A43: Nombre | B43: Mensual | C43: Quincenal | D43: Es Anual | H43: Cuenta Cargo | I43: Cuenta Deposito
A44: Trading | B44: =CEILING(F44,100) -> 500 | C44: =CEILING(B44/2, 10) -> 250 | D44: =IF(E44>0, true) -> FALSE | F44: 450 | H44: HSBC | I44: GBM Trading
A45: Dolares | B45: =CEILING(F45,100) -> 500 | C45: =CEILING(B45/2, 10) -> 250 | D45: =IF(E45>0, true) -> FALSE | F45: 450 | H45: HSBC | I45: GBM Dolares
A46: Largo plazo | B46: =CEILING(F46,100) -> 1100 | C46: =CEILING(B46/2, 10) -> 550 | D46: =IF(E46>0, true) -> FALSE | F46: 1100 | H46: Stori Inversion + | I46: Stori Inversion +
A48: Total | B48: =SUM(B44:B46) -> 2100 | C48: =SUM(C44:C46) -> 1050 | F48: =SUM(F44:F46) -> 2000
...

Sheet Gastos Viaje Texas Dec 25
A1: WORLD ELITE
A2: Hugo Boss San Marcos | B2: 2093.93
A3: BROOKSHIRE BROS 626 | B3: 486.98
A4: Adidas AMERICA, INC. | B4: 2804.14
A5: ROSS STORES #548 | B5: 4659.13
A6: WM SUPERCENTER #6929 | B6: 2005.46
A7: MARSHALLS #819 | B7: 6461
A8: NikePOS_US | B8: 1266.04
A9: BUC-EE'S #0035 | B9: 778.95
B12: =SUM(B2:B11) -> 20555.63
A14: AMERICAN EXPRESS
A15: Tablet Amazon | B15: 2692.35
A16: Amazon US | B16: 365.97
A17: Amazon US | B17: 600.27
A18: Pizzeria | B18: 3560.57
A19: Paradies | B19: 311.23
A20: Freezing Pont | B20: 392.97
A21: Old fashiond soda | B21: 361.7
A22: Santas wonderland | B22: 369.27
A23: Blitzend parking | B23: 391.8
A24: Chevron | B24: 59.66
A25: Chevron | B25: 51.56
A26: CHISHOLM TRAIL CHUCKWAG | B26: 296.89
... A34: CROCS | B34: 2248.98
A35: Shake shack | B35: =1092.03+257.98 -> 1350.01
A36: SUNOCO | B36: 161.07
A37: Sunoco | B37: 454.17
A38: Paradies | B38: 73.36
A39: PS store * | B39: 255.77
A40: Digital Ocean * | B40: 110.92
B45: =SUM(B14:B40) -> 18942.52

Sheet Until 31.12.2024
A1: 39 | J1: Mensual | K1: Quincenal
A2: Nombre | B2: Mensual | C2: Quincenal | D2: Es Anual | E2: Cuenta Cargo | F2: Cuenta Deposito | I2: Total | J2: =B15+B30+B39+B47+B59+B75+B82 -> 139664.5 | K2: =C15+C30+C39+C47+C59+C82+C75 -> 69832.25
A3: Colegiatura Lena | B3: 15770 | C3: =B3/2 -> 7885 | D3: FALSE | E3: HSBC World elite | F3: Uala
A4: Colegiatura Leander | B4: 7915 | C4: =B4/2 -> 3957.5 | D4: FALSE | E4: HSBC | F4: Uala
A5: Futbol | B5: =1300+(1300*0.9) -> 2470 | C5: =B5/2 -> 1235 | D5: FALSE | E5: HSBC World elite | F5: Nu Cajita Gastos
A6: Lena Robotica | B6: 1100 | C6: =B6/2 -> 550 | D6: FALSE | E6: HSBC World elite | F6: Uala | G6: =B3+B6+B7+B10+B11 -> 20245
A7: Lena Yoga | B7: 1100 | C7: =B7/2 -> 550 | D7: FALSE | E7: HSBC World elite | F7: Uala
A8: Horario Extendido Leander | B8: 2200 | C8: =B8/2 -> 1100 | D8: FALSE | E8: HSBC | F8: Uala
A9: Ballet | B9: 1200 | C9: =B9/2 -> 600 | D9: FALSE | E9: Nu Dalia Debito | F9: Nu Dalia Debito
A10: Natacion Lena | B10: 1180 | C10: =B10/2 -> 590 | D10: FALSE | E10: HSBC World elite | F10: Uala
A11: Natacion Leander | B11: 1095 | C11: =B11/2 -> 547.5 | D11: FALSE | E11: HSBC World elite | F11: Uala
A12: Inscripcion Lena | B12: =15000/12 -> 1250 | C12: =B12/2 -> 625 | D12: TRUE | E12: HSBC | F12: Stori +
A13: Inscripcion Leander | B13: 750 | C13: =B13/2 -> 375 | D13: TRUE | E13: HSBC | F13: Stori + | M13: 45550 | N13: 45565 | O13: 45580 | P13: 45596 | Q13: 45611 | R13: 45626 | S13: 15 Dic 24 | T13: 31 Dic 24
I14: Total Mensual | J14: Total quincenal | K14: Programada
A15: Total | B15: =SUM(B2:B14) -> 36030 | C15: =SUM(C2:C14) -> 18015 | H15: Cetes | I15: =CEILING(SUMIF($F$2:$F$86, H15, $B$2:$B$86),100) -> 8000 | J15: =CEILING(SUMIF($F$2:$F$86, H15, $C$2:$C$86),100) -> 4000 | K15: Si (Portal Cetes) | M15: TRUE | N15: TRUE | O15: TRUE | P15: TRUE | Q15: TRUE | R15: TRUE | S15: TRUE | T15: TRUE
H16: GBM Trading | I16: =CEILING(SUMIF($F$2:$F$86, H16, $B$2:$B$86),100) -> 600 | J16: =CEILING(SUMIF($F$2:$F$86, H16, $C$2:$C$86),100) -> 300 | K16: No | M16: TRUE | N16: TRUE | O16: TRUE | P16: TRUE | Q16: TRUE | R16: TRUE | S16: TRUE | T16: FALSE
A17: Suscripciones | H17: GBM Dolares | I17: =CEILING(SUMIF($F$2:$F$86, H17, $B$2:$B$86),100) -> 600 | J17: =CEILING(SUMIF($F$2:$F$86, H17, $C$2:$C$86),100) -> 300 | K17: No | M17: TRUE | N17: TRUE | O17: TRUE | P17: TRUE | Q17: TRUE | R17: TRUE | S17: TRUE | T17: FALSE
A18: Nombre | B18: Mensual | C18: Quincenal | H18: HSBC | I18: =CEILING(SUMIF($F$2:$F$86, H18, $B$2:$B$86),100) -> 10800 | J18: =CEILING(SUMIF($F$2:$F$86, H18, $C$2:$C$86),100) -> 5400 | K18: No | M18: FALSE | N18: FALSE | O18: FALSE | P18: FALSE | Q18: FALSE | R18: FALSE | S18: FALSE | T18: FALSE
A19: Sports World | B19: 3600 | C19: =B19/2 -> 1800 | D19: FALSE | E19: HSBC World elite | F19: Nu Cajita Gastos | H19: HSBC Flexible | I19: =CEILING(SUMIF($F$2:$F$86, H19, $B$2:$B$86),100) -> 37500 | J19: =CEILING(SUMIF($F$2:$F$86, H19, $C$2:$C$86),100) -> 18800 | K19: No | M19: TRUE | N19: TRUE | O19: TRUE | P19: TRUE | Q19: FALSE | R19: TRUE | S19: TRUE | T19: TRUE
A20: Netflix | B20: =CEILING(299,10) -> 300 | C20: =B20/2 -> 150 | D20: FALSE | E20: HSBC World elite | F20: Nu Cajita Gastos | H20: Nu Cajita Auto | I20: =CEILING(SUMIF($F$2:$F$86, H20, $B$2:$B$86),100) -> 16300 | J20: =CEILING(SUMIF($F$2:$F$86, H20, $C$2:$C$86),100) -> 8200 | K20: No | M20: TRUE | N20: TRUE | O20: TRUE | P20: TRUE | Q20: TRUE | R20: TRUE | S20: TRUE | T20: TRUE
A21: Disney | B21: 299 | C21: =B21/2 -> 149.5 | D21: FALSE | E21: HSBC World elite | F21: Nu Cajita Gastos | H21: Nu Cajita Gastos | I21: =CEILING(SUMIF($F$2:$F$86, H21, $B$2:$B$86),100) -> 27600 | J21: =CEILING(SUMIF($F$2:$F$86, H21, $C$2:$C$86),100) -> 13800 | K21: No | M21: TRUE | N21: TRUE | O21: FALSE | P21: TRUE | Q21: TRUE | R21: TRUE | S21: TRUE | T21: FALSE
A22: NFL game pass | B22: =CEILING(3000/12, 10) -> 250 | C22: =B22/2 -> 125 | D22: TRUE | E22: HSBC Air | F22: Stori + | H22: Nu Dalia Debito | I22: =CEILING(SUMIF($F$2:$F$86, H22, $B$2:$B$86),100) -> 3900 | J22: =CEILING(SUMIF($F$2:$F$86, H22, $C$2:$C$86),100) -> 2000 | K22: No | M22: TRUE | N22: TRUE | O22: TRUE | P22: TRUE | Q22: TRUE | R22: TRUE | S22: TRUE | T22: TRUE
A23: Spotify | B23: 200 | C23: =B23/2 -> 100 | D23: TRUE | E23: HSBC Air | F23: Stori + | H23: Santander | I23: =CEILING(SUMIF($F$2:$F$86, H23, $B$2:$B$86),100) -> 0 | J23: =CEILING(SUMIF($F$2:$F$86, H23, $C$2:$C$86),100) -> 0 | K23: No | M23: TRUE | N23: TRUE | O23: TRUE | P23: TRUE | Q23: TRUE | R23: TRUE | S23: TRUE | T23: TRUE
A24: HBO | B24: =CEILING(199,10) -> 200 | C24: =B24/2 -> 100 | D24: FALSE | E24: HSBC World elite | F24: Nu Cajita Gastos | H24: Stori + | I24: =CEILING(SUMIF($F$2:$F$86, H24, $B$2:$B$86),100) -> 4100 | J24: =CEILING(SUMIF($F$2:$F$86, H24, $C$2:$C$86),100) -> 2100 | K24: No | M24: TRUE | N24: TRUE | O24: TRUE | P24: TRUE | Q24: TRUE | R24: TRUE | S24: TRUE | T24: TRUE
A25: Digital Ocean | B25: =IFERROR(__xludf.DUMMYFUNCTION("CEILING(GOOGLEFINANCE(""CURRENCY:USDMXN"")*6, 10)"),110.0) -> 110 | C25: =B25/2 -> 55 | D25: FALSE | E25: HSBC World elite | F25: Nu Cajita Gastos | H25: Uala | I25: =CEILING(SUMIF($F$2:$F$86, H25, $B$2:$B$86),100) -> 30400 | J25: =CEILING(SUMIF($F$2:$F$86, H25, $C$2:$C$86),100) -> 15200 | M25: TRUE | N25: TRUE | O25: TRUE | P25: TRUE | Q25: TRUE | R25: TRUE | S25: TRUE | T25: TRUE
A26: Prime | B26: =CEILING(899/12, 10) -> 80 | C26: =B26/2 -> 40 | D26: TRUE | E26: HSBC Air | F26: Stori +
A27: Uber one | B27: 70 | C27: =B27/2 -> 35 | D27: TRUE | E27: HSBC Air | F27: Stori + | I27: =SUM(I15:I25) -> 139800 | J27: =SUM(J15:J25) -> 70100
A28: Frontend masters | B28: 0 | C28: =B28/2 -> 0 | D28: FALSE | E28: HSBC World elite | F28: Nu Cajita Gastos
A30: Total | B30: =SUM(B19:B28) -> 5109 | C30: =SUM(C19:C28) -> 2554.5
A33: Telecomunicaciones | L33: =J25+J15 -> 19200
A34: Nombre | B34: Mensual | C34: Quincenal
A35: Totalplay (Internet + TV) | B35: 1200 | C35: =B35/2 -> 600 | D35: FALSE | E35: HSBC World elite | F35: Nu Cajita Gastos
A36: Movistar Dalia | B36: 500 | C36: =B36/2 -> 250 | D36: FALSE | E36: HSBC World elite | F36: Nu Cajita Gastos
A37: Movistar Alfredo | B37: 450 | C37: =B37/2 -> 225 | D37: FALSE | E37: HSBC World elite | F37: Nu Cajita Gastos
A39: Total | B39: =SUM(B35:B38) -> 2150 | C39: =SUM(C35:C38) -> 1075
L40: ¡
A41: Ahorro
A42: Nombre | B42: Mensual | C42: Quincenal
A43: Largo plazo | B43: 8000 | C43: =B43/2 -> 4000 | D43: FALSE | E43: HSBC | F43: Cetes
A44: Trading | B44: 600 | C44: =B44/2 -> 300 | D44: FALSE | E44: HSBC | F44: GBM Trading | H44: HSBC World elite | I44: =CEILING(SUMIF($E$2:$E$86, H44, $B$2:$B$86),100) -> 45800 | J44: =CEILING(SUMIF($E$2:$E$86, H44, $C$2:$C$86),100) -> 22900
...

Sheet Until 15.05.2024
A1: Kinder | J1: Mensual | K1: Quincenal
A2: Nombre | B2: Mensual | C2: Quincenal | D2: Es Anual | I2: Total | J2: =B13+B28+B36+B44+B55+B69+B77 -> 132405 | K2: =C13+C28+C36+C44+C55+C77+C69 -> 66202.5
A3: Inscripcion Leander | B3: =CEILING((7500)/12, 100) -> 700 | C3: =B3/2 -> 350 | D3: TRUE | E3: Klar
A4: Inscripcion Lena | B4: =CEILING((9500)/12, 100) -> 800 | C4: =B4/2 -> 400 | D4: TRUE | E4: Klar
A5: Ballet | B5: 1200 | C5: =B5/2 -> 600 | D5: FALSE | E5: Nu Dalia
A6: Colegiatura Leander | B6: =CEILING(7124,100) -> 7200 | C6: =B6/2 -> 3600 | D6: FALSE | E6: HSBC Ahorro
A7: Colegiatura Lena | B7: =CEILING(7520, 100) -> 7600 | C7: =B7/2 -> 3800 | D7: FALSE | E7: HSBC Ahorro
A8: Horario Extendido Lena | B8: 2200 | C8: =B8/2 -> 1100 | D8: FALSE | E8: HSBC Ahorro
A9: Horario Extendido Leander | B9: 2200 | C9: =B9/2 -> 1100 | D9: FALSE | E9: HSBC Ahorro
A10: Natacion Leander | B10: 1095 | C10: =B10/2 -> 547.5 | D10: FALSE | E10: HSBC Ahorro
A11: Natacion Lena | B11: 1180 | C11: =B11/2 -> 590 | D11: FALSE | E11: HSBC Ahorro
I12: Total Mensual | J12: Total quincenal | K12: Programada
A13: Total | B13: =SUM(B2:B12) -> 24175 | C13: =SUM(C2:C12) -> 12087.5 | H13: Nu Dalia | I13: =CEILING(SUMIF($E$2:$E$80, H13, $B$2:$B$80),100) -> 3200 | J13: =CEILING(SUMIF($E$2:$E$80, H13, $C$2:$C$80),100) -> 1600 | K13: SI
H14: HSBC Ahorro | I14: =CEILING(SUMIF($E$2:$E$80, H14, $B$2:$B$80),100) -> 59000 | J14: =CEILING(SUMIF($E$2:$E$80, H14, $C$2:$C$80),100) -> 29500 | K14: Si
A15: Suscripciones | H15: Nu | I15: =CEILING(SUMIF($E$2:$E$80, H15, $B$2:$B$80),100) -> 17800 | J15: =CEILING(SUMIF($E$2:$E$80, H15, $C$2:$C$80),100) -> 8900 | K15: Si
A16: Nombre | B16: Mensual | C16: Quincenal | H16: Klar | I16: =CEILING(SUMIF($E$2:$E$80, H16, $B$2:$B$80),100) -> 3100 | J16: =CEILING(SUMIF($E$2:$E$80, H16, $C$2:$C$80),100) -> 1600 | K16: Si (hacia NU)
A17: Prime | B17: =CEILING(899/12, 10) -> 80 | C17: =B17/2 -> 40 | D17: TRUE | E17: Klar | H17: Cetes | I17: =CEILING(SUMIF($E$2:$E$80, H17, $B$2:$B$80),100) -> 6000 | J17: =CEILING(SUMIF($E$2:$E$80, H17, $C$2:$C$80),100) -> 3000 | K17: Si (Portal Cetes)
A18: NFL game pass | B18: =CEILING(2500/12, 10) -> 210 | C18: =B18/2 -> 105 | D18: TRUE | E18: Klar | H18: GBM | I18: =CEILING(SUMIF($E$2:$E$80, H18, $B$2:$B$80),100) -> 2000 | J18: =CEILING(SUMIF($E$2:$E$80, H18, $C$2:$C$80),100) -> 1000 | K18: Si
A19: Digital Ocean | B19: =IFERROR(__xludf.DUMMYFUNCTION("CEILING(GOOGLEFINANCE(""CURRENCY:USDMXN"")*6, 10)"),110.0) -> 110 | C19: =B19/2 -> 55 | D19: FALSE | E19: Stori + | H19: Santander | I19: =CEILING(SUMIF($E$2:$E$80, H19, $B$2:$B$80),100) -> 14800 | J19: =CEILING(SUMIF($E$2:$E$80, H19, $C$2:$C$80),100) -> 7400 | K19: Si
A20: Paramount | B20: =CEILING(109,10) -> 110 | C20: =B20/2 -> 55 | D20: FALSE | E20: Stori + | H20: Stori + | I20: =CEILING(SUMIF($E$2:$E$80, H20, $B$2:$B$80),100) -> 4800 | J20: =CEILING(SUMIF($E$2:$E$80, H20, $C$2:$C$80),100) -> 2400 | K20: Si
A21: HBO | B21: =CEILING(399/3,10) -> 140 | C21: =B21/2 -> 70 | D21: FALSE | E21: Stori + | H21: HSBC | I21: =CEILING(SUMIF($E$2:$E$80, H21, $B$2:$B$80),100) -> 20100 | J21: =CEILING(SUMIF($E$2:$E$80, H21, $C$2:$C$80),100) -> 10100
A22: Disney | B22: =CEILING(249,10) -> 250 | C22: =B22/2 -> 125 | D22: FALSE | E22: Stori + | H22: BBVA | I22: =CEILING(SUMIF($E$2:$E$80, H22, $B$2:$B$80),100) -> 1800 | J22: =CEILING(SUMIF($E$2:$E$80, H22, $C$2:$C$80),100) -> 900 | K22: Si
A23: Netflix | B23: =CEILING(299,10) -> 300 | C23: =B23/2 -> 150 | D23: FALSE | E23: Stori +
A24: Frontend masters | B24: =IFERROR(__xludf.DUMMYFUNCTION("CEILING(GOOGLEFINANCE(""CURRENCY:USDMXN"")*39, 10)"),680.0) -> 680 | C24: =B24/2 -> 340 | D24: FALSE | E24: Stori +
A25: Uber one | B25: 70 | C25: =B25/2 -> 35 | D25: FALSE | E25: Stori +
A26: Spotify | B26: 200 | C26: =B26/2 -> 100 | D26: FALSE | E26: Stori + | J26: =SUM(J13:J22) -> 66400
A28: Total | B28: =SUM(B17:B27) -> 2150 | C28: =SUM(C17:C27) -> 1075
A30: Telecomunicaciones
A31: Nombre | B31: Mensual | C31: Quincenal
A32: Movistar Dalia | B32: 500 | C32: =B32/2 -> 250 | D32: FALSE | E32: Stori +
A33: Movistar Alfredo | B33: 600 | C33: =B33/2 -> 300 | D33: FALSE | E33: Stori +
A34: Totalplay (Internet + TV) | B34: 1200 | C34: =B34/2 -> 600 | D34: FALSE | E34: Stori +
A36: Total | B36: =SUM(B32:B35) -> 2300 | C36: =SUM(C32:C35) -> 1150
A38: Ahorro
A39: Nombre | B39: Mensual | C39: Quincenal
A40: Personal | B40: 2000 | C40: =B40/2 -> 1000 | D40: FALSE | E40: GBM
A41: Largo plazo | B41: 6000 | C41: =B41/2 -> 3000 | D41: FALSE | E41: Cetes
A42: Nuevo Auto | B42: 9000 | C42: =B42/2 -> 4500 | D42: FALSE | E42: Nu
A44: Total | B44: =SUM(B40:B43) -> 17000 | C44: =SUM(C40:C43) -> 8500
A46: Auto
...

Sheet Until 31.07.23
A1: Subscripciones | B1: Mensual | C1: Quincenal | F1: Seguros, mantenimiento, sin categoría | G1: Mensual | H1: Quincenal
